2025-06-16 17:51:39,384 [INFO] TOR connection set via SOCKS5 at 127.0.0.1:9050
2025-06-16 17:51:41,966 [INFO] Checking IP via Tor...
2025-06-16 17:51:41,972 [DEBUG] Starting new HTTPS connection (1): check.torproject.org:443
2025-06-16 17:51:43,988 [DEBUG] Error connecting to SOCKS5 proxy 127.0.0.1:9050 due to: [WinError 10061] No connection could be made because the target machine actively refused it
2025-06-16 17:51:43,994 [ERROR] Check IP failed:
Traceback (most recent call last):
  File "C:\Users\Admin\.conda\envs\py-kivy\lib\site-packages\socks.py", line 787, in connect
    super(socksocket, self).connect(proxy_addr)
ConnectionRefusedError: [WinError 10061] No connection could be made because the target machine actively refused it

During handling of the above exception, another exception occurred:

Traceback (most recent call last):
  File "C:\Users\Admin\.conda\envs\py-kivy\lib\site-packages\urllib3\connection.py", line 198, in _new_conn
    sock = connection.create_connection(
  File "C:\Users\Admin\.conda\envs\py-kivy\lib\site-packages\urllib3\util\connection.py", line 85, in create_connection
    raise err
  File "C:\Users\Admin\.conda\envs\py-kivy\lib\site-packages\urllib3\util\connection.py", line 73, in create_connection
    sock.connect(sa)
  File "C:\Users\Admin\.conda\envs\py-kivy\lib\site-packages\socks.py", line 47, in wrapper
    return function(*args, **kwargs)
  File "C:\Users\Admin\.conda\envs\py-kivy\lib\site-packages\socks.py", line 800, in connect
    raise ProxyConnectionError(msg, error)
socks.ProxyConnectionError: Error connecting to SOCKS5 proxy 127.0.0.1:9050: [WinError 10061] No connection could be made because the target machine actively refused it

The above exception was the direct cause of the following exception:

Traceback (most recent call last):
  File "C:\Users\Admin\.conda\envs\py-kivy\lib\site-packages\urllib3\connectionpool.py", line 787, in urlopen
    response = self._make_request(
  File "C:\Users\Admin\.conda\envs\py-kivy\lib\site-packages\urllib3\connectionpool.py", line 488, in _make_request
    raise new_e
  File "C:\Users\Admin\.conda\envs\py-kivy\lib\site-packages\urllib3\connectionpool.py", line 464, in _make_request
    self._validate_conn(conn)
  File "C:\Users\Admin\.conda\envs\py-kivy\lib\site-packages\urllib3\connectionpool.py", line 1093, in _validate_conn
    conn.connect()
  File "C:\Users\Admin\.conda\envs\py-kivy\lib\site-packages\urllib3\connection.py", line 704, in connect
    self.sock = sock = self._new_conn()
  File "C:\Users\Admin\.conda\envs\py-kivy\lib\site-packages\urllib3\connection.py", line 213, in _new_conn
    raise NewConnectionError(
urllib3.exceptions.NewConnectionError: <urllib3.connection.HTTPSConnection object at 0x0000019E510BA670>: Failed to establish a new connection: Error connecting to SOCKS5 proxy 127.0.0.1:9050: [WinError 10061] No connection could be made because the target machine actively refused it

The above exception was the direct cause of the following exception:

Traceback (most recent call last):
  File "C:\Users\Admin\.conda\envs\py-kivy\lib\site-packages\requests\adapters.py", line 667, in send
    resp = conn.urlopen(
  File "C:\Users\Admin\.conda\envs\py-kivy\lib\site-packages\urllib3\connectionpool.py", line 841, in urlopen
    retries = retries.increment(
  File "C:\Users\Admin\.conda\envs\py-kivy\lib\site-packages\urllib3\util\retry.py", line 519, in increment
    raise MaxRetryError(_pool, url, reason) from reason  # type: ignore[arg-type]
urllib3.exceptions.MaxRetryError: HTTPSConnectionPool(host='check.torproject.org', port=443): Max retries exceeded with url: / (Caused by NewConnectionError('<urllib3.connection.HTTPSConnection object at 0x0000019E510BA670>: Failed to establish a new connection: Error connecting to SOCKS5 proxy 127.0.0.1:9050: [WinError 10061] No connection could be made because the target machine actively refused it'))

During handling of the above exception, another exception occurred:

Traceback (most recent call last):
  File "D:\py-kivy-tor\main-gui.py", line 34, in check_ip
    ip = requests.get("https://check.torproject.org", timeout=15).text
  File "C:\Users\Admin\.conda\envs\py-kivy\lib\site-packages\requests\api.py", line 73, in get
    return request("get", url, params=params, **kwargs)
  File "C:\Users\Admin\.conda\envs\py-kivy\lib\site-packages\requests\api.py", line 59, in request
    return session.request(method=method, url=url, **kwargs)
  File "C:\Users\Admin\.conda\envs\py-kivy\lib\site-packages\requests\sessions.py", line 589, in request
    resp = self.send(prep, **send_kwargs)
  File "C:\Users\Admin\.conda\envs\py-kivy\lib\site-packages\requests\sessions.py", line 703, in send
    r = adapter.send(request, **kwargs)
  File "C:\Users\Admin\.conda\envs\py-kivy\lib\site-packages\requests\adapters.py", line 700, in send
    raise ConnectionError(e, request=request)
requests.exceptions.ConnectionError: HTTPSConnectionPool(host='check.torproject.org', port=443): Max retries exceeded with url: / (Caused by NewConnectionError('<urllib3.connection.HTTPSConnection object at 0x0000019E510BA670>: Failed to establish a new connection: Error connecting to SOCKS5 proxy 127.0.0.1:9050: [WinError 10061] No connection could be made because the target machine actively refused it'))

2025-06-16 17:51:47,103 [INFO] Checking IP via Tor...
2025-06-16 17:51:47,105 [DEBUG] Starting new HTTPS connection (1): check.torproject.org:443
2025-06-16 17:51:49,115 [DEBUG] Error connecting to SOCKS5 proxy 127.0.0.1:9050 due to: [WinError 10061] No connection could be made because the target machine actively refused it
2025-06-16 17:51:49,116 [ERROR] Check IP failed:
Traceback (most recent call last):
  File "C:\Users\Admin\.conda\envs\py-kivy\lib\site-packages\socks.py", line 787, in connect
    super(socksocket, self).connect(proxy_addr)
ConnectionRefusedError: [WinError 10061] No connection could be made because the target machine actively refused it

During handling of the above exception, another exception occurred:

Traceback (most recent call last):
  File "C:\Users\Admin\.conda\envs\py-kivy\lib\site-packages\urllib3\connection.py", line 198, in _new_conn
    sock = connection.create_connection(
  File "C:\Users\Admin\.conda\envs\py-kivy\lib\site-packages\urllib3\util\connection.py", line 85, in create_connection
    raise err
  File "C:\Users\Admin\.conda\envs\py-kivy\lib\site-packages\urllib3\util\connection.py", line 73, in create_connection
    sock.connect(sa)
  File "C:\Users\Admin\.conda\envs\py-kivy\lib\site-packages\socks.py", line 47, in wrapper
    return function(*args, **kwargs)
  File "C:\Users\Admin\.conda\envs\py-kivy\lib\site-packages\socks.py", line 800, in connect
    raise ProxyConnectionError(msg, error)
socks.ProxyConnectionError: Error connecting to SOCKS5 proxy 127.0.0.1:9050: [WinError 10061] No connection could be made because the target machine actively refused it

The above exception was the direct cause of the following exception:

Traceback (most recent call last):
  File "C:\Users\Admin\.conda\envs\py-kivy\lib\site-packages\urllib3\connectionpool.py", line 787, in urlopen
    response = self._make_request(
  File "C:\Users\Admin\.conda\envs\py-kivy\lib\site-packages\urllib3\connectionpool.py", line 488, in _make_request
    raise new_e
  File "C:\Users\Admin\.conda\envs\py-kivy\lib\site-packages\urllib3\connectionpool.py", line 464, in _make_request
    self._validate_conn(conn)
  File "C:\Users\Admin\.conda\envs\py-kivy\lib\site-packages\urllib3\connectionpool.py", line 1093, in _validate_conn
    conn.connect()
  File "C:\Users\Admin\.conda\envs\py-kivy\lib\site-packages\urllib3\connection.py", line 704, in connect
    self.sock = sock = self._new_conn()
  File "C:\Users\Admin\.conda\envs\py-kivy\lib\site-packages\urllib3\connection.py", line 213, in _new_conn
    raise NewConnectionError(
urllib3.exceptions.NewConnectionError: <urllib3.connection.HTTPSConnection object at 0x0000019E55F01460>: Failed to establish a new connection: Error connecting to SOCKS5 proxy 127.0.0.1:9050: [WinError 10061] No connection could be made because the target machine actively refused it

The above exception was the direct cause of the following exception:

Traceback (most recent call last):
  File "C:\Users\Admin\.conda\envs\py-kivy\lib\site-packages\requests\adapters.py", line 667, in send
    resp = conn.urlopen(
  File "C:\Users\Admin\.conda\envs\py-kivy\lib\site-packages\urllib3\connectionpool.py", line 841, in urlopen
    retries = retries.increment(
  File "C:\Users\Admin\.conda\envs\py-kivy\lib\site-packages\urllib3\util\retry.py", line 519, in increment
    raise MaxRetryError(_pool, url, reason) from reason  # type: ignore[arg-type]
urllib3.exceptions.MaxRetryError: HTTPSConnectionPool(host='check.torproject.org', port=443): Max retries exceeded with url: / (Caused by NewConnectionError('<urllib3.connection.HTTPSConnection object at 0x0000019E55F01460>: Failed to establish a new connection: Error connecting to SOCKS5 proxy 127.0.0.1:9050: [WinError 10061] No connection could be made because the target machine actively refused it'))

During handling of the above exception, another exception occurred:

Traceback (most recent call last):
  File "D:\py-kivy-tor\main-gui.py", line 34, in check_ip
    ip = requests.get("https://check.torproject.org", timeout=15).text
  File "C:\Users\Admin\.conda\envs\py-kivy\lib\site-packages\requests\api.py", line 73, in get
    return request("get", url, params=params, **kwargs)
  File "C:\Users\Admin\.conda\envs\py-kivy\lib\site-packages\requests\api.py", line 59, in request
    return session.request(method=method, url=url, **kwargs)
  File "C:\Users\Admin\.conda\envs\py-kivy\lib\site-packages\requests\sessions.py", line 589, in request
    resp = self.send(prep, **send_kwargs)
  File "C:\Users\Admin\.conda\envs\py-kivy\lib\site-packages\requests\sessions.py", line 703, in send
    r = adapter.send(request, **kwargs)
  File "C:\Users\Admin\.conda\envs\py-kivy\lib\site-packages\requests\adapters.py", line 700, in send
    raise ConnectionError(e, request=request)
requests.exceptions.ConnectionError: HTTPSConnectionPool(host='check.torproject.org', port=443): Max retries exceeded with url: / (Caused by NewConnectionError('<urllib3.connection.HTTPSConnection object at 0x0000019E55F01460>: Failed to establish a new connection: Error connecting to SOCKS5 proxy 127.0.0.1:9050: [WinError 10061] No connection could be made because the target machine actively refused it'))

2025-06-16 17:51:53,451 [INFO] TOR connection set via SOCKS5 at 127.0.0.1:9050
2025-06-16 17:51:54,089 [INFO] Pinging website: example.com
2025-06-16 17:51:57,383 [INFO] Ping success.
2025-06-16 17:52:07,695 [INFO] Pinging website: www.facebook.com
2025-06-16 17:52:10,738 [INFO] Ping success.
2025-06-16 17:52:43,423 [INFO] Pinging website: www.facebook.com
2025-06-16 17:52:46,463 [INFO] Ping success.
